Workbook

Sheet Read me
A1: Dream OS Capability Map
A2: Competitive capability map, researched 31 August 2026
A4: What this is
A5: 122 estate-agency capabilities, and whether each of the four systems worth learning from does it.
A6: The four columns were checked against vendor documentation and help centres, not affiliate review sites.
A8: The four systems
A9: BoldTrail — US, formerly kvCORE, ~400,000 agents. The famous one: lead conversion, IDX, dialer, AI, back office.
A10: Reapit — UK, 15,000 branches. The incumbent, and the platform architecture is the lesson.
A11: Street.co.uk — UK challenger. The best modern execution of the whole agency workflow.
A12: Entegral Base — SA, R949/month for up to 50 users. What Bronwyn could buy tomorrow, so it is the price ceiling.
A14: How to use it
A15: Column K, Decision, is a dropdown: Must have / Nice to have / Not for us. Pick one per row.
... A29: A practitioner may not accept a mandate without a signed mandatory disclosure form, annexed to the sale. If it is missing, the agreement reads as though no defects were disclosed. (Row M11)

Sheet Capability map
A1: ID | B1: Area | C1: Capability | D1: Why it matters | E1: BoldTrail | F1: Reapit | G1: Street.co.uk | H1: Entegral Base | I1: Dream OS today | J1: Dream OS note | K1: Decision | L1: Note
A2: C01 | B2: Contacts & leads | C2: Contact record with multiple roles | D2: One person who is a seller here and a buyer there, without duplicate records | E2: Yes | F2: Yes | G2: Yes | H2: Yes | I2: Built | J2: party table + role timeline on /contacts
A3: C02 | B3: Contacts & leads | C3: Buyer requirement profile | D3: Area, price band, beds, must-haves — stored, not in the agent's head | E3: Yes | F3: Yes | G3: Yes | H3: Yes | I3: Planned | J3: party_interest in migration 0066, no UI
A4: C03 | B4: Contacts & leads | C4: Buyer-to-listing matching | D4: Show me everything on our books this buyer should see | E4: Yes | F4: Yes | G4: Yes | H4: Yes | I4: Not yet
A5: C04 | B5: Contacts & leads | C5: Reverse matching on new stock | D5: New listing lands, system names the buyers to ring first | E5: Partial | F5: Yes | G5: Yes | H5: Yes | I5: Not yet
A6: C05 | B6: Contacts & leads | C6: Portal enquiry straight into the CRM | D6: P24 / Private Property leads arrive as records, not inbox clutter | E6: Yes | F6: Yes | G6: Yes | H6: Yes | I6: Partial | J6: email intake parses enquiries; no portal feed
A7: C06 | B7: Contacts & leads | C7: Lead source attribution | D7: Which portal, campaign or board brought this buyer | E7: Yes | F7: Partial | G7: Yes | H7: Yes | I7: Planned | J7: contact_source enum, unwired
A8: C07 | B8: Contacts & leads | C8: Automatic lead routing | D8: Round-robin, by suburb, by price band — assigned without a human | E8: Yes | F8: Partial | G8: Yes | H8: Partial | I8: Not yet
A9: C08 | B9: Contacts & leads | C9: Lead scoring | D9: Rank who is actually close to transacting | E9: Yes | F9: Not confirmed | G9: Partial | H9: No | I9: Not yet
A10: C09 | B10: Contacts & leads | C10: Duplicate detection & merge | D10: The same seller entered three ways, caught before it spreads | E10: Partial | F10: Partial | G10: Partial | H10: Not confirmed | I10: Built | J10: match_candidate dedup pipeline
A11: C10 | B11: Contacts & leads | C11: Full interaction timeline | D11: Every call, mail, viewing and document on one record | E11: Yes | F11: Yes | G11: Yes | H11: Yes | I11: Built
A12: L01 | B12: Listings & property data | C12: Listing record with status pipeline | D12: Preparing → listed → under offer → sold, as states not labels | E12: Yes | F12: Yes | G12: Yes | H12: Yes | I12: Built
A13: L02 | B13: Listings & property data | C13: Freehold vs sectional title as structure | D13: Drives which clearance certificate and which third party — not a tag | E13: No | F13: Partial | G13: Partial | H13: Partial | I13: Built | J13: ownership_type × property_type seeded
A14: L03 | B14: Listings & property data | C14: Erf / cadastral parcel data | D14: The stand itself as a record, with its diagram and boundaries | E14: No | F14: No | G14: No | H14: No | I14: Built | J14: cadastral_parcel + erf, /erf-lookup, tile server
A15: L04 | B15: Listings & property data | C15: Map with cadastral polygons | D15: Shaded erven, not pins floating on a basemap | E15: Partial | F15: Partial | G15: Partial | H15: Partial | I15: Built | J15: MapView.tsx, plan 005 shipped
A16: L05 | B16: Listings & property data | C16: Municipal valuation roll | D16: What the municipality thinks it's worth, next to what we're asking | E16: No | F16: No | G16: No | H16: No | I16: Built | J16: muni_valuation + upload/parse/apply
A17: L06 | B17: Listings & property data | C17: Deeds / title enrichment | D17: Registered owner, purchase date and price pulled automatically | E17: Partial | F17: Partial | G17: Partial | H17: Partial | I17: Built | J17: Lightstone, budget-capped
A18: L07 | B18: Listings & property data | C18: Competitor stock ingest | D18: Everything on the market in Knysna, not only our own mandates | E18: Partial | F18: No | G18: No | H18: No | I18: Built | J18: P24 scraper; geocoding still unreliable
A19: L08 | B19: Listings & property data | C19: Photo & media library | D19: Ordered, captioned, reusable across marketing | E19: Yes | F19: Yes | G19: Yes | H19: Yes | I19: Built | J19: media bucket + lightbox
A20: L09 | B20: Listings & property data | C20: Floorplans | D20: Drawn or uploaded, shown on the listing | E20: Yes | F20: Yes | G20: Yes | H20: Not confirmed | I20: Not yet
A21: L10 | B21: Listings & property data | C21: Virtual tours & video | D21: 360° or walkthrough attached to the listing | E21: Yes | F21: Partial | G21: Yes | H21: Yes | I21: Not yet
A22: L11 | B22: Listings & property data | C22: Brochure & window card generation | D22: Branded PDF off the listing data, no designer in the loop | E22: Yes | F22: Yes | G22: Yes | H22: Yes | I22: Not yet
A23: L12 | B23: Listings & property data | C23: Price history | D23: Every reduction, dated, for the CMA conversation | E23: Yes | F23: Yes | G23: Yes | H23: Partial | I23: Built | J23: listing_price_history
A24: M01 | B24: Mandates | C24: Mandate as a first-class record | D24: The instruction to market, not just a listing with a date on it | E24: No | F24: Yes | G24: Yes | H24: Partial | I24: Built | J24: mandate table + /mandates
A25: M02 | B25: Mandates | C25: Mandate types modelled properly | D25: Sole, open, joint, multi-listing — each with its own rules | E25: No | F25: Yes | G25: Yes | H25: Not confirmed | I25: Partial | J25: sole and exclusive are two enum values for one thing — consolidate
A26: M03 | B26: Mandates | C26: Expiry tracking with auto-expire | D26: Lapsed mandates stop counting as live stock on their own | E26: No | F26: Yes | G26: Yes | H26: Yes | I26: Built | J26: threshold watchlist on /mandates
A27: M04 | B27: Mandates | C27: Renewal reminders before expiry | D27: Prompted to re-sign in time, not after the seller has gone | E27: No | F27: Yes | G27: Yes | H27: Yes | I27: Built | J27: mandate.expiry_window_days setting
A28: M05 | B28: Mandates | C28: Mandate generated from a template | D28: The real master document, filled from the record | E28: Partial | F28: Partial | G28: Partial | H28: No | I28: Partial | J28: MandateSole.tsx built from the wrong master — replace wholesale
A29: M06 | B29: Mandates | C29: Clause library with variants | D29: One clause, several approved wordings, chosen per deal | E29: No | F29: No | G29: No | H29: No | I29: Planned | J29: 0065_document_engine.sql written, not applied
A30: M07 | B30: Mandates | C30: E-signature on the mandate | D30: Signed on Bronwyn's iPad at the kitchen table | E30: Yes | F30: Partial | G30: Partial | H30: No | I30: Not yet
A31: M08 | B31: Mandates | C31: Signed mandate stored and findable | D31: "What did we send the Wilsons in March" has an answer | E31: Yes | F31: Yes | G31: Yes | H31: Partial | I31: Not yet | J31: generated mandates write no document row today
A32: M09 | B32: Mandates | C32: Joint-mandate counterparty agency | D32: Pam Golding on the other side, and the split that follows | E32: No | F32: Yes | G32: Partial | H32: Not confirmed | I32: Built | J32: agency table exists for exactly this
A33: M10 | B33: Mandates | C33: CPA duration & notice rules enforced | D33: 24-month cap, 20-day cancellation, pre-expiry notice — in the software | E33: No | F33: No | G33: No | H33: No | I33: Not yet | J33: nobody does this; verify sections before coding
A34: M11 | B34: Mandates | C34: Mandatory disclosure form | D34: Signed by the seller before we take the mandate, annexed to the sale | E34: No | F34: No | G34: Partial | H34: No | I34: Not yet | J34: no signed form, no valid mandate — and the agreement then reads as defect-free
A35: V01 | B35: Viewings & vendor care | C35: Viewing scheduling | D35: Diary of who sees what, when, with which agent | E35: Partial | F35: Yes | G35: Yes | H35: Partial | I35: Built | J35: viewing table + weekly /viewings calendar
A36: V02 | B36: Viewings & vendor care | C36: Buyer books their own viewing | D36: Self-service slots, 24/7, no phone tag | E36: Partial | F36: Partial | G36: Yes | H36: No | I36: Not yet
A37: V03 | B37: Viewings & vendor care | C37: Show day management | D37: Open house with attendee capture, walk-ins included | E37: Yes | F37: Yes | G37: Yes | H37: Partial | I37: Built | J37: walk-in names captured without a party record
A38: V04 | B38: Viewings & vendor care | C38: Structured viewing feedback | D38: Interested / not / why — as data, not a note | E38: No | F38: Yes | G38: Yes | H38: Partial | I38: Built | J38: viewing_attendee.is_interested tri-state
A39: V05 | B39: Viewings & vendor care | C39: Automated feedback request | D39: The buyer gets asked without anyone remembering to ask | E39: Partial | F39: Partial | G39: Yes | H39: No | I39: Not yet
A40: V06 | B40: Viewings & vendor care | C40: Vendor progress report | D40: Weekly "here's what happened on your house" going out automatically | E40: No | F40: Yes | G40: Yes | H40: Yes | I40: Not yet | J40: the single cheapest seller-retention feature on this sheet
...

Sheet Summary
A1: Where the decisions stand
A2: These cells are formulas. They update as you fill in column K of the map.
A4: Decision | B4: Rows
A5: Must have | B5: =COUNTIF('Capability map'!$K$2:$K$123,A5) -> 0
A6: Nice to have | B6: =COUNTIF('Capability map'!$K$2:$K$123,A6) -> 0
A7: Not for us | B7: =COUNTIF('Capability map'!$K$2:$K$123,A7) -> 0
A8: Still undecided | B8: =COUNTBLANK('Capability map'!$K$2:$K$123) -> 122
A9: Total capabilities | B9: =COUNTA('Capability map'!$A$2:$A$123) -> 122
A11: By area
A12: Area | B12: Rows | C12: Must have | D12: Dream OS built | E12: Dream OS not yet
A13: Contacts & leads | B13: =COUNTIF('Capability map'!$B$2:$B$123,$A13) -> 10 | C13: =COUNTIFS('Capability map'!$B$2:$B$123,$A13,'Capability map'!$K$2:$K$123,"Must have") -> 0 | D13: =COUNTIFS('Capability map'!$B$2:$B$123,$A13,'Capability map'!$I$2:$I$123,"Built") -> 3 | E13: =COUNTIFS('Capability map'!$B$2:$B$123,$A13,'Capability map'!$I$2:$I$123,"Not yet") -> 4
A14: Listings & property data | B14: =COUNTIF('Capability map'!$B$2:$B$123,$A14) -> 12 | C14: =COUNTIFS('Capability map'!$B$2:$B$123,$A14,'Capability map'!$K$2:$K$123,"Must have") -> 0 | D14: =COUNTIFS('Capability map'!$B$2:$B$123,$A14,'Capability map'!$I$2:$I$123,"Built") -> 9 | E14: =COUNTIFS('Capability map'!$B$2:$B$123,$A14,'Capability map'!$I$2:$I$123,"Not yet") -> 3
A15: Mandates | B15: =COUNTIF('Capability map'!$B$2:$B$123,$A15) -> 11 | C15: =COUNTIFS('Capability map'!$B$2:$B$123,$A15,'Capability map'!$K$2:$K$123,"Must have") -> 0 | D15: =COUNTIFS('Capability map'!$B$2:$B$123,$A15,'Capability map'!$I$2:$I$123,"Built") -> 4 | E15: =COUNTIFS('Capability map'!$B$2:$B$123,$A15,'Capability map'!$I$2:$I$123,"Not yet") -> 4
A16: Viewings & vendor care | B16: =COUNTIF('Capability map'!$B$2:$B$123,$A16) -> 9 | C16: =COUNTIFS('Capability map'!$B$2:$B$123,$A16,'Capability map'!$K$2:$K$123,"Must have") -> 0 | D16: =COUNTIFS('Capability map'!$B$2:$B$123,$A16,'Capability map'!$I$2:$I$123,"Built") -> 3 | E16: =COUNTIFS('Capability map'!$B$2:$B$123,$A16,'Capability map'!$I$2:$I$123,"Not yet") -> 5
A17: Offers & deal progression | B17: =COUNTIF('Capability map'!$B$2:$B$123,$A17) -> 12 | C17: =COUNTIFS('Capability map'!$B$2:$B$123,$A17,'Capability map'!$K$2:$K$123,"Must have") -> 0 | D17: =COUNTIFS('Capability map'!$B$2:$B$123,$A17,'Capability map'!$I$2:$I$123,"Built") -> 5 | E17: =COUNTIFS('Capability map'!$B$2:$B$123,$A17,'Capability map'!$I$2:$I$123,"Not yet") -> 5
A18: Money — commission & trust | B18: =COUNTIF('Capability map'!$B$2:$B$123,$A18) -> 9 | C18: =COUNTIFS('Capability map'!$B$2:$B$123,$A18,'Capability map'!$K$2:$K$123,"Must have") -> 0 | D18: =COUNTIFS('Capability map'!$B$2:$B$123,$A18,'Capability map'!$I$2:$I$123,"Built") -> 0 | E18: =COUNTIFS('Capability map'!$B$2:$B$123,$A18,'Capability map'!$I$2:$I$123,"Not yet") -> 9
A19: Documents & signature | B19: =COUNTIF('Capability map'!$B$2:$B$123,$A19) -> 8 | C19: =COUNTIFS('Capability map'!$B$2:$B$123,$A19,'Capability map'!$K$2:$K$123,"Must have") -> 0 | D19: =COUNTIFS('Capability map'!$B$2:$B$123,$A19,'Capability map'!$I$2:$I$123,"Built") -> 1 | E19: =COUNTIFS('Capability map'!$B$2:$B$123,$A19,'Capability map'!$I$2:$I$123,"Not yet") -> 2
A20: Compliance — FICA, POPIA, PPRA | B20: =COUNTIF('Capability map'!$B$2:$B$123,$A20) -> 9 | C20: =COUNTIFS('Capability map'!$B$2:$B$123,$A20,'Capability map'!$K$2:$K$123,"Must have") -> 0 | D20: =COUNTIFS('Capability map'!$B$2:$B$123,$A20,'Capability map'!$I$2:$I$123,"Built") -> 5 | E20: =COUNTIFS('Capability map'!$B$2:$B$123,$A20,'Capability map'!$I$2:$I$123,"Not yet") -> 2
A21: Communication | B21: =COUNTIF('Capability map'!$B$2:$B$123,$A21) -> 10 | C21: =COUNTIFS('Capability map'!$B$2:$B$123,$A21,'Capability map'!$K$2:$K$123,"Must have") -> 0 | D21: =COUNTIFS('Capability map'!$B$2:$B$123,$A21,'Capability map'!$I$2:$I$123,"Built") -> 1 | E21: =COUNTIFS('Capability map'!$B$2:$B$123,$A21,'Capability map'!$I$2:$I$123,"Not yet") -> 7
A22: Marketing, portals & web presence | B22: =COUNTIF('Capability map'!$B$2:$B$123,$A22) -> 9 | C22: =COUNTIFS('Capability map'!$B$2:$B$123,$A22,'Capability map'!$K$2:$K$123,"Must have") -> 0 | D22: =COUNTIFS('Capability map'!$B$2:$B$123,$A22,'Capability map'!$I$2:$I$123,"Built") -> 0 | E22: =COUNTIFS('Capability map'!$B$2:$B$123,$A22,'Capability map'!$I$2:$I$123,"Not yet") -> 9
A23: AI | B23: =COUNTIF('Capability map'!$B$2:$B$123,$A23) -> 8 | C23: =COUNTIFS('Capability map'!$B$2:$B$123,$A23,'Capability map'!$K$2:$K$123,"Must have") -> 0 | D23: =COUNTIFS('Capability map'!$B$2:$B$123,$A23,'Capability map'!$I$2:$I$123,"Built") -> 1 | E23: =COUNTIFS('Capability map'!$B$2:$B$123,$A23,'Capability map'!$I$2:$I$123,"Not yet") -> 7
A24: Reporting | B24: =COUNTIF('Capability map'!$B$2:$B$123,$A24) -> 7 | C24: =COUNTIFS('Capability map'!$B$2:$B$123,$A24,'Capability map'!$K$2:$K$123,"Must have") -> 0 | D24: =COUNTIFS('Capability map'!$B$2:$B$123,$A24,'Capability map'!$I$2:$I$123,"Built") -> 1 | E24: =COUNTIFS('Capability map'!$B$2:$B$123,$A24,'Capability map'!$I$2:$I$123,"Not yet") -> 6
A25: Platform | B25: =COUNTIF('Capability map'!$B$2:$B$123,$A25) -> 8 | C25: =COUNTIFS('Capability map'!$B$2:$B$123,$A25,'Capability map'!$K$2:$K$123,"Must have") -> 0 | D25: =COUNTIFS('Capability map'!$B$2:$B$123,$A25,'Capability map'!$I$2:$I$123,"Built") -> 1 | E25: =COUNTIFS('Capability map'!$B$2:$B$123,$A25,'Capability map'!$I$2:$I$123,"Not yet") -> 5
A26: Total | B26: =SUM(B13:B25) -> 122 | C26: =SUM(C13:C25) -> 0 | D26: =SUM(D13:D25) -> 34 | E26: =SUM(E13:E25) -> 68
